Workbook

Sheet Synthèse
A1: REDIMENSIONNEMENT — DÉPARTEMENT 41 (LOIR-ET-CHER)
A2: Objectif : SAV joignable à J+1/J+2 sur les 12 secteurs · PROD planifiée à J+5/J+6/J+7 · volumes majorés de 10 %
A3: Source volumes : suivi_volumes_PROD_72.xlsx (MAJ 28/07/2026), onglets « Suivi des volumes PROD » et « Volume par NRO » — 12 secteurs GRDV, 59 NRO.
A4: Cadence PROD retro-calculée depuis le fichier source : Nbr tech nécessaire = ARRONDI.SUP(Moy/Jr mars / 4) — règle vérifiée sur 256 des 263 lignes du fichier (97 %).
A6: 1 · PARAMÈTRES DE DIMENSIONNEMENT
A7: Paramètre | B7: Valeur | C7: Unité | D7: Origine / commentaire
A8: Marge de flexibilité appliquée aux volumes | B8: 0.1 | C8: % | D8: Demande client : +10 % sur l'estimation de volumes
A9: Cadence PROD (moyenne département) | B9: 4 | C9: inter./tech./jour | D9: Rétro-calculée sur le fichier source (97 % de concordance)
A10: Cadence PROD en demi-journée locale | B10: 5 | C10: inter./tech./jour | D10: Après-midi passée dans le secteur du SAV du matin : pas de trajet inter-secteur
A11: Cadence SAV — Blois (ZMD dense) | B11: 7 | C11: créneaux/jour | D11: Capture d'écran : journée Blois = 7 créneaux
A12: Cadence SAV — ZMD secondaire | B12: 6 | C12: créneaux/jour | D12: Vendôme, Romorantin
A13: Cadence SAV — secteurs ruraux (RIP) | B13: 5 | C13: créneaux/jour | D13: Capture d'écran : matin 3 + après-midi 2
A14: Jours ouvrés PROD / mois — base octobre | B14: 25 | C14: jours | D14: Déduit du fichier : Moy/JR (octobre) = volume / 25
A15: Jours ouvrés PROD / mois — base mars | B15: 24 | C15: jours | D15: Déduit du fichier : Moy/JR (mars) = volume / 24
A16: Jours ouvrés B2B / mois | B16: 22 | C16: jours | D16: Déduit du fichier : Moy/Jr (B2B) = volume / 22
A17: Semaines par mois | B17: 4.3333 | C17: semaines | D17: Conversion mensuel → hebdomadaire
A18: Taux de présence des techniciens | B18: 1 | C18: % | D18: 1,00 = aucun congé/arrêt/formation. Mettre 0,88 pour un scénario réaliste.
A19: Taux de remplissage attendu des créneaux SAV | B19: 0.5 | C19: % | D19: Part des créneaux SAV réservés réellement consommés. Curseur clé.
A21: 2 · EFFECTIF DISPONIBLE
A22: Poste | B22: Valeur | C22: Unité | D22: Commentaire
A23: Nombre total de techniciens | B23: 11 | C23: tech. | D23: Effectif actuel déclaré
A24: dont travaillant 6 jours / semaine | B24: 5 | C24: tech. | D24: Déclaré — ce sont eux qui portent le rythme Mardi-Jeudi-Samedi
A25: dont travaillant 5 jours / semaine | B25: =B23-B24 | C25: tech. | D25: total − techniciens 6 jours
A26: Technicien 100 % SAV aujourd'hui | B26: 1 | C26: tech. | D26: Déclaré
A27: Jours-technicien bruts / semaine | B27: =B24*6+B25*5 | C27: j-tech | D27: 6 j × techs 6 jours + 5 j × techs 5 jours
A28: Jours-technicien nets / semaine | B28: =B27*$B$18 | C28: j-tech | D28: bruts × taux de présence
A29: Jours-technicien nets / mois | B29: =B28*$B$17 | C29: j-tech
A30: Jours-technicien par technicien / semaine | B30: =B27/B23 | C30: j-tech | D30: Moyenne pondérée, sert au calcul d'ETP
A32: 3 · VERDICT CAPACITAIRE
A33: Poste | B33: Jours-tech / sem. | C33: Interventions / sem. | D33: Lecture
A34: Capacité nette disponible | B34: =$B$28 | D34: Ce que l'équipe peut produire, tous types d'intervention confondus
A35: Charge PROD estimée +10 % | B35: ='Demande 41'!$L$18 | C35: ='Demande 41'!$K$18 | D35: Volume du fichier source, mois le plus chargé, B2B inclus, majoré de 10 %
A36: Solde mobilisable pour le SAV | B36: =$B$34-$B$35 | D36: Tout ce qui reste une fois la PROD servie dans le délai J+5/J+7
A37: Charge moyenne d'un créneau SAV | B37: ='Demande 41'!$P$18/'Demande 41'!$O$18 | D37: Pondérée par la répartition Blois / ruraux de la grille
A38: Créneaux SAV finançables / semaine | C38: =$B$36/$B$37 | D38: PLAFOND : au-delà, la PROD décroche du délai J+5/J+7
A39: Créneaux SAV réservés dans la grille | C39: ='Grille SAV'!$D$34 | D39: Réservation ≠ consommation : les créneaux non vendus rebasculent en PROD à J-1
A40: Créneaux SAV réellement consommés | C40: =$C$39*$B$19 | D40: réservés × taux de remplissage
A41: Marge (+) ou dépassement (−) | C41: =$C$38-$C$40 | D41: ="Seuil d'équilibre : "&TEXT($C$38/$C$39,"0 %")&" de remplissage des créneaux réservés, soit "&TEXT($C$38,"0")&" interventions SAV/semaine ("&TEXT($C$38*4.3333,"0")&"/mois)"
A42: VERDICT | B42: =IF($C$41>=0,"TENABLE — "&TEXT($C$41,"0")&" créneaux SAV/sem. de marge à taux de remplissage "&TEXT($B$19,"0%"),"INTENABLE — il manque "&TEXT(-$C$41,"0")&" créneaux SAV/sem., soit "&TEXT(-$C$41*$B$37/$B$30,"0.0")&" technicien(s) supplémentaire(s)")
A44: 4 · SENSIBILITÉ — TECHNICIENS REQUIS SELON LE VOLUME SAV RÉEL
...

Sheet Scénarios
A1: TROIS SCÉNARIOS DE PLANIFICATION — DÉPARTEMENT 41
A2: Comparés à effectif constant (11 techniciens, 60 jours-technicien par semaine) et à demande PROD identique (+10 %).
A4: Critère | B4: A — Grille actuelle (capture) | C4: B — Rythme L-Me-V / Ma-J-S (RECOMMANDÉ) | D4: C — Renfort +2 techniciens
A5: Techniciens dédiés SAV | B5: 5 techniciens SAV pleins + 6 PROD | C5: 1 SAV pur + 5 référents mixtes + 5 PROD | D5: 1 SAV pur + 5 référents + 7 PROD
A6: Effectif total | B6: 11 | C6: 11 | D6: 13
A7: Jours-technicien / semaine | B7: 60 | C7: 60 | D7: 70
A8: Secteurs tenant le J+1/J+2 | B8: 3 sur 12 (Blois, Pontlevoy, Vendôme) | C8: 12 sur 12 | D8: 12 sur 12
A9: Passages SAV / semaine / secteur | B9: 1 à 5 selon le secteur — Cormenon et Vouzon : 1 seul | C9: 3 minimum partout | D9: 3 à 4
A10: Créneaux SAV réservés / semaine | B10: 142 | C10: 149 | D10: 149
A11: Interventions PROD servies en direct | B11: ≈ 140 | C11: 142 | D11: 192
A12: Demande PROD +10 % à servir | B12: 185 | C12: 185 | D12: 185
A13: Écart PROD avant bascule | B13: − 45 / semaine | C13: − 43 / semaine | D13: + 7 / semaine
A14: Comblé par la bascule J-1 ? | B14: Non prévue dans le modèle actuel | C14: Oui : ≈ 48 interventions récupérées | D14: Sans objet
A15: Taux de remplissage SAV maximal | B15: non tenable au-delà de ~20 % | C15: 60 % | D15: 100 %
... A20: Coût | B20: Constant | C20: Constant | D20: + 2 salaires
A21: RECOMMANDATION | B21: Basculer sur le scénario B immédiatement : il ne coûte rien et fait passer le respect du J+1/J+2 de 3 à 12 secteurs. Ne déclencher le scénario C que si le volume SAV réel mesuré dépasse 90 interventions par semaine sur le département.
A23: LEVIERS DE LIBÉRATION DE DISPONIBILITÉ, PAR ORDRE DE RENTABILITÉ
A24: Levier | B24: Mécanisme | C24: Gain estimé | D24: Coût
A25: 1. Rythme L-Me-V / Ma-J-S | B25: Trois passages par semaine sur chaque secteur au lieu de 1 ou 2. | C25: J+1/J+2 tenu sur 12 secteurs au lieu de 3 | D25: Nul — réorganisation
A26: 2. Bascule J-1 des créneaux SAV | B26: Tout créneau SAV non vendu à J-1 18 h est rempli par une PROD du carnet J+5/J+7. | C26: ≈ 48 interventions PROD/sem. récupérées | D26: Nul — règle d'ordonnancement
A27: 3. Journées mixtes SAV + PROD | B27: L'après-midi se fait dans le secteur du SAV du matin : plus de trajet inter-secteur. | C27: Cadence PROD 4 → 5 sur ces demi-journées, soit ≈ 2 j-tech/sem. | D27: Nul
A28: 4. Samedi des 5 techniciens à 6 j | B28: Affecter les 6-jours aux secteurs du rythme Mardi-Jeudi-Samedi. | C28: Couvre les appels du jeudi et du vendredi | D28: Nul — déjà payé
A29: 5. Recomposition géographique | B29: Cormenon rattaché au Nord et non à la Sologne Est. | C29: −16 km sur l'enchaînement le plus long | D29: Nul
A30: 6. Renfort d'effectif | B30: Deux techniciens supplémentaires. | C30: +10 j-tech/sem., soit ≈ 55 créneaux SAV | D30: 2 salaires

Sheet Grille SAV
A1: GRILLE HEBDOMADAIRE PROPOSÉE — 11 TECHNICIENS · DÉPARTEMENT 41
A2: Principe : la tournée (technicien × jour × secteur) est FIGÉE. Seul le partage SAV / PROD à l'intérieur de la journée est variable.
A3: Chaque secteur est visité 3 fois par semaine sur un rythme Lundi-Mercredi-Vendredi OU Mardi-Jeudi-Samedi : c'est ce qui garantit un créneau SAV à J+1 ou J+2 quel que soit le jour d'appel.
A4: SAV = créneaux réservés, ouverts à la prise de RDV J+1/J+2. PROD = interventions pré-affectées depuis le carnet J+5/J+7. Les créneaux SAV non vendus basculent en PROD à J-1 18 h (voir onglet « Moteur dispo »).
A6: Tech. | B6: Rôle / cluster | C6: Jours /sem. | D6: Lundi — matin | E6: Lundi — après-midi | F6: Mardi — matin | G6: Mardi — après-midi | H6: Mercredi — matin | I6: Mercredi — après-midi | J6: Jeudi — matin | K6: Jeudi — après-midi | L6: Vendredi — matin | M6: Vendredi — après-midi | N6: Samedi — matin | O6: Samedi — après-midi | P6: SAV réservés /sem. | Q6: PROD servies /sem.
A7: T1 | B7: Blois — référent SAV | C7: 5 | D7: Blois SAV 4 | E7: Blois SAV 3 | F7: Blois SAV 4 | G7: Blois SAV 3 | H7: Blois SAV 4 | I7: Blois SAV 3 | J7: Blois SAV 4 | K7: Blois SAV 3 | L7: Blois SAV 4 | M7: Blois SAV 3 | N7: repos | O7: repos | P7: 35 | Q7: 0
A8: T2 | B8: Blois — mixte SAV/PROD | C8: 6 | D8: Blois SAV 4 | E8: Blois PROD 2 | F8: Blois SAV 4 | G8: Blois PROD 2 | H8: Blois SAV 4 | I8: Blois PROD 2 | J8: Blois SAV 4 | K8: Blois PROD 2 | L8: Blois SAV 4 | M8: Blois PROD 2 | N8: Blois SAV 4 | O8: Blois PROD 2 | P8: 24 | Q8: 12
A9: T3 | B9: Sud-Ouest — Pontlevoy / Valencisse | C9: 6 | D9: Pontlevoy SAV 3 | E9: Pontlevoy PROD 2 | F9: Valencisse SAV 3 | G9: Valencisse PROD 2 | H9: Pontlevoy SAV 3 | I9: Pontlevoy PROD 2 | J9: Valencisse SAV 3 | K9: Valencisse PROD 2 | L9: Pontlevoy SAV 3 | M9: Pontlevoy PROD 2 | N9: Valencisse SAV 3 | O9: Valencisse PROD 2 | P9: 18 | Q9: 12
A10: T4 | B10: Nord — Vendômois / Perche / Beauce | C10: 6 | D10: Vendôme SAV 3 | E10: Épiais SAV 2 | F10: Montoire SAV 3 | G10: Cormenon SAV 2 | H10: Vendôme SAV 3 | I10: Épiais SAV 2 | J10: Montoire SAV 3 | K10: Cormenon SAV 2 | L10: Vendôme SAV 3 | M10: Épiais SAV 2 | N10: Montoire SAV 3 | O10: Cormenon SAV 2 | P10: 30 | Q10: 0
A11: T5 | B11: Sologne Sud — Mur / Romorantin / La Ferté | C11: 6 | D11: Mur-de-Sologne SAV 3 | E11: Mur-de-Sologne PROD 2 | F11: Romorantin SAV 3 | G11: La Ferté-Imb. SAV 2 | H11: Mur-de-Sologne SAV 3 | I11: Mur-de-Sologne PROD 2 | J11: Romorantin SAV 3 | K11: La Ferté-Imb. SAV 2 | L11: Mur-de-Sologne SAV 3 | M11: Mur-de-Sologne PROD 2 | N11: Romorantin SAV 3 | O11: La Ferté-Imb. SAV 2 | P11: 24 | Q11: 6
A12: T6 | B12: Sologne Est — Crouy / Vouzon | C12: 6 | D12: Crouy-s-Cosson SAV 3 | E12: Crouy-s-Cosson PROD 2 | F12: Vouzon SAV 3 | G12: Vouzon PROD 2 | H12: Crouy-s-Cosson SAV 3 | I12: Crouy-s-Cosson PROD 2 | J12: Vouzon SAV 3 | K12: Vouzon PROD 2 | L12: Crouy-s-Cosson SAV 3 | M12: Crouy-s-Cosson PROD 2 | N12: Vouzon SAV 3 | O12: Vouzon PROD 2 | P12: 18 | Q12: 12
A13: T7 | B13: PROD — Blois agglo | C13: 5 | D13: Blois PROD 2 | E13: Blois PROD 2 | F13: Blois PROD 2 | G13: Blois PROD 2 | H13: Blois PROD 2 | I13: Blois PROD 2 | J13: Blois PROD 2 | K13: Blois PROD 2 | L13: Blois PROD 2 | M13: Blois PROD 2 | N13: repos | O13: repos | P13: 0 | Q13: 20
A14: T8 | B14: PROD — Blois agglo | C14: 5 | D14: Blois PROD 2 | E14: Blois PROD 2 | F14: Blois PROD 2 | G14: Blois PROD 2 | H14: Blois PROD 2 | I14: Blois PROD 2 | J14: Blois PROD 2 | K14: Blois PROD 2 | L14: Blois PROD 2 | M14: Blois PROD 2 | N14: repos | O14: repos | P14: 0 | Q14: 20
A15: T9 | B15: PROD — Nord (Vendômois/Beauce) | C15: 5 | D15: Vendôme PROD 2 | E15: Épiais PROD 2 | F15: Vendôme PROD 2 | G15: Épiais PROD 2 | H15: Vendôme PROD 2 | I15: Épiais PROD 2 | J15: Vendôme PROD 2 | K15: Épiais PROD 2 | L15: Vendôme PROD 2 | M15: Épiais PROD 2 | N15: repos | O15: repos | P15: 0 | Q15: 20
A16: T10 | B16: PROD — Sologne | C16: 5 | D16: Romorantin PROD 2 | E16: Mur-de-Sologne PROD 2 | F16: Romorantin PROD 2 | G16: Mur-de-Sologne PROD 2 | H16: Romorantin PROD 2 | I16: Mur-de-Sologne PROD 2 | J16: Romorantin PROD 2 | K16: Mur-de-Sologne PROD 2 | L16: Romorantin PROD 2 | M16: Mur-de-Sologne PROD 2 | N16: repos | O16: repos | P16: 0 | Q16: 20
A17: T11 | B17: PROD — Sud-Ouest / Val de Cher | C17: 5 | D17: Pontlevoy PROD 2 | E17: Pontlevoy PROD 2 | F17: Pontlevoy PROD 2 | G17: Pontlevoy PROD 2 | H17: Pontlevoy PROD 2 | I17: Pontlevoy PROD 2 | J17: Pontlevoy PROD 2 | K17: Pontlevoy PROD 2 | L17: Pontlevoy PROD 2 | M17: Pontlevoy PROD 2 | N17: repos | O17: repos | P17: 0 | Q17: 20
A18: TOTAL | C18: =SUM(C7:C17) | P18: =SUM(P7:P17) | Q18: =SUM(Q7:Q17)
A20: CONTRÔLE DU DÉLAI SAV J+1 / J+2 — SECTEUR PAR SECTEUR
A21: Secteur | B21: Jours de passage SAV | C21: Passages /sem. | D21: Créneaux SAV réservés /sem. | E21: Rythme | F21: Délai SAV J+1/J+2 | G21: Charge SAV (j-tech/sem.)
A22: Blois | B22: Lun · Mar · Mer · Jeu · Ven · Sam | C22: 6 | D22: 59 | E22: Quotidien | F22: =IF($C22>=3,"OK","À CORRIGER") | G22: =IFERROR($D22/INDEX('Demande 41'!$M$6:$M$17,MATCH($A22,'Demande 41'!$A$6:$A$17,0)),"")
A23: Pontlevoy | B23: Lun · Mer · Ven | C23: 3 | D23: 9 | E23: L-Me-V | F23: =IF($C23>=3,"OK","À CORRIGER") | G23: =IFERROR($D23/INDEX('Demande 41'!$M$6:$M$17,MATCH($A23,'Demande 41'!$A$6:$A$17,0)),"")
A24: Valencisse | B24: Mar · Jeu · Sam | C24: 3 | D24: 9 | E24: Ma-J-S | F24: =IF($C24>=3,"OK","À CORRIGER") | G24: =IFERROR($D24/INDEX('Demande 41'!$M$6:$M$17,MATCH($A24,'Demande 41'!$A$6:$A$17,0)),"")
A25: Vendôme | B25: Lun · Mer · Ven | C25: 3 | D25: 9 | E25: L-Me-V | F25: =IF($C25>=3,"OK","À CORRIGER") | G25: =IFERROR($D25/INDEX('Demande 41'!$M$6:$M$17,MATCH($A25,'Demande 41'!$A$6:$A$17,0)),"")
A26: Épiais | B26: Lun · Mer · Ven | C26: 3 | D26: 6 | E26: L-Me-V | F26: =IF($C26>=3,"OK","À CORRIGER") | G26: =IFERROR($D26/INDEX('Demande 41'!$M$6:$M$17,MATCH($A26,'Demande 41'!$A$6:$A$17,0)),"")
A27: Montoire-sur-le-Loir | B27: Mar · Jeu · Sam | C27: 3 | D27: 9 | E27: Ma-J-S | F27: =IF($C27>=3,"OK","À CORRIGER") | G27: =IFERROR($D27/INDEX('Demande 41'!$M$6:$M$17,MATCH($A27,'Demande 41'!$A$6:$A$17,0)),"")
A28: Cormenon | B28: Mar · Jeu · Sam | C28: 3 | D28: 6 | E28: Ma-J-S | F28: =IF($C28>=3,"OK","À CORRIGER") | G28: =IFERROR($D28/INDEX('Demande 41'!$M$6:$M$17,MATCH($A28,'Demande 41'!$A$6:$A$17,0)),"")
A29: Crouy-sur-Cosson | B29: Lun · Mer · Ven | C29: 3 | D29: 9 | E29: L-Me-V | F29: =IF($C29>=3,"OK","À CORRIGER") | G29: =IFERROR($D29/INDEX('Demande 41'!$M$6:$M$17,MATCH($A29,'Demande 41'!$A$6:$A$17,0)),"")
A30: Vouzon | B30: Mar · Jeu · Sam | C30: 3 | D30: 9 | E30: Ma-J-S | F30: =IF($C30>=3,"OK","À CORRIGER") | G30: =IFERROR($D30/INDEX('Demande 41'!$M$6:$M$17,MATCH($A30,'Demande 41'!$A$6:$A$17,0)),"")
A31: Mur-de-Sologne | B31: Lun · Mer · Ven | C31: 3 | D31: 9 | E31: L-Me-V | F31: =IF($C31>=3,"OK","À CORRIGER") | G31: =IFERROR($D31/INDEX('Demande 41'!$M$6:$M$17,MATCH($A31,'Demande 41'!$A$6:$A$17,0)),"")
A32: Romorantin-Lanthenay | B32: Mar · Jeu · Sam | C32: 3 | D32: 9 | E32: Ma-J-S | F32: =IF($C32>=3,"OK","À CORRIGER") | G32: =IFERROR($D32/INDEX('Demande 41'!$M$6:$M$17,MATCH($A32,'Demande 41'!$A$6:$A$17,0)),"")
A33: La Ferté-Imbault | B33: Mar · Jeu · Sam | C33: 3 | D33: 6 | E33: Ma-J-S | F33: =IF($C33>=3,"OK","À CORRIGER") | G33: =IFERROR($D33/INDEX('Demande 41'!$M$6:$M$17,MATCH($A33,'Demande 41'!$A$6:$A$17,0)),"")
A34: TOTAL | B34: 12 secteurs | D34: =SUM(D22:D33) | G34: =SUM(G22:G33)
A36: Les 5 techniciens à 6 jours sont les 5 référents ruraux (T2 à T6) : c'est le samedi qui rend possible le rythme Mardi-Jeudi-Samedi, donc la tenue du J+1/J+2 sur la moitié des secteurs.
A37: Enchaînements matin → après-midi sur deux secteurs différents : Vendôme→Épiais 29 km · Montoire→Cormenon 30 km · Romorantin→La Ferté-Imbault 22 km. Tous les autres enchaînements restent dans le même secteur.

Sheet Effectif
A1: AFFECTATION DES 11 TECHNICIENS
A2: 5 techniciens à 6 jours + 6 techniciens à 5 jours = 60 jours-technicien par semaine.
A4: Tech. | B4: Rôle | C4: Cluster | D4: Jours /sem. | E4: Base conseillée | F4: Secteurs couverts | G4: Type de journée
A5: T1 | B5: Référent SAV Blois | C5: Blois | D5: 5 | E5: Blois | F5: Blois | G5: SAV toute la journée
A6: T2 | B6: Blois mixte | C6: Blois | D6: 6 | E6: Blois | F6: Blois | G6: SAV matin / PROD après-midi
A7: T3 | B7: Référent Sud-Ouest | C7: Sud-Ouest | D7: 6 | E7: Pontlevoy ou Montrichard | F7: Pontlevoy (L-Me-V) · Valencisse (Ma-J-S) | G7: SAV matin / PROD après-midi
A8: T4 | B8: Référent Nord | C8: Nord | D8: 6 | E8: Vendôme | F8: Vendôme + Épiais (L-Me-V) · Montoire + Cormenon (Ma-J-S) | G8: SAV matin et après-midi
A9: T5 | B9: Référent Sologne Sud | C9: Sologne Sud | D9: 6 | E9: Romorantin-Lanthenay | F9: Mur-de-Sologne (L-Me-V) · Romorantin + La Ferté-Imbault (Ma-J-S) | G9: Mixte selon le jour
A10: T6 | B10: Référent Sologne Est | C10: Est | D10: 6 | E10: Crouy-sur-Cosson ou Lamotte-Beuvron | F10: Crouy-sur-Cosson (L-Me-V) · Vouzon (Ma-J-S) | G10: SAV matin / PROD après-midi
A11: T7 | B11: PROD Blois agglo | C11: Blois | D11: 5 | E11: Blois | F11: Blois | G11: PROD
A12: T8 | B12: PROD Blois agglo | C12: Blois | D12: 5 | E12: Blois | F12: Blois | G12: PROD
A13: T9 | B13: PROD Nord | C13: Nord | D13: 5 | E13: Vendôme | F13: Vendôme · Épiais · Montoire · Cormenon | G13: PROD
A14: T10 | B14: PROD Sologne | C14: Sologne Sud | D14: 5 | E14: Romorantin-Lanthenay | F14: Romorantin · Mur-de-Sologne · La Ferté-Imbault · Vouzon | G14: PROD
A15: T11 | B15: PROD Sud-Ouest | C15: Sud-Ouest | D15: 5 | E15: Pontlevoy | F15: Pontlevoy · Valencisse | G15: PROD
A16: TOTAL | B16: =COUNTA(A5:A15)&" techniciens" | D16: =SUM(D5:D15) | F16: 12 secteurs GRDV couverts
A18: Fond orange = les 5 techniciens travaillant 6 jours. Ce sont eux qui doivent porter les secteurs du rythme Mardi-Jeudi-Samedi : sans leur samedi, aucun créneau SAV n'existe à J+1/J+2 pour un appel du jeudi ou du vendredi.
A19: Le technicien 100 % SAV déjà en poste devient T1 sur Blois, qui concentre 34 % du volume départemental.

Sheet Demande 41
A1: DEMANDE & CHARGE PAR SECTEUR — DÉPARTEMENT 41
A2: Colonnes E-G : volumes bruts du fichier source. Colonne O (bleue) : volume SAV réel — À RENSEIGNER, c'est la donnée qui pilote tout le dimensionnement.
A3: Charge exprimée en jours-technicien par semaine (1 j-tech = 1 technicien × 1 journée). Le total ligne 18 alimente l'onglet Synthèse.
A5: Secteur GRDV | B5: Commune pivot | C5: Zone | D5: Cluster géo. | E5: Dist. Blois (km) | F5: PROD octobre (inter./mois) | G5: PROD mars (inter./mois) | H5: B2B (inter./mois) | I5: Pointe /jour (B2B inclus) | J5: Pointe /jour +10 % | K5: PROD /semaine +10 % | L5: Charge PROD (j-tech/sem.) | M5: Cadence SAV (créneaux/j) | N5: SAV réservé /sem. (grille) | O5: SAV RÉEL /sem. (à saisir) | P5: Charge SAV (j-tech/sem.) | Q5: Charge totale (j-tech/sem.) | R5: Techniciens équivalents
A6: Blois | B6: Blois | C6: ZMD | D6: Blois | E6: 0 | F6: 240 | G6: 218 | H6: 3 | I6: =MAX($F6/'Synthèse'!$B$14,$G6/'Synthèse'!$B$15)+$H6/'Synthèse'!$B$16 | J6: =$I6*(1+'Synthèse'!$B$8) | K6: =(MAX($F6,$G6)+$H6)*(1+'Synthèse'!$B$8)/'Synthèse'!$B$17 | L6: =$K6/'Synthèse'!$B$9 | M6: ='Synthèse'!$B$11 | N6: 59 | O6: 35 | P6: =$O6/$M6 | Q6: =$L6+$P6 | R6: =$Q6/'Synthèse'!$B$30
A7: Valencisse | B7: Valencisse | C7: RIP | D7: Sud-Ouest | E7: 11 | F7: 43 | G7: 42 | H7: 0.67 | I7: =MAX($F7/'Synthèse'!$B$14,$G7/'Synthèse'!$B$15)+$H7/'Synthèse'!$B$16 | J7: =$I7*(1+'Synthèse'!$B$8) | K7: =(MAX($F7,$G7)+$H7)*(1+'Synthèse'!$B$8)/'Synthèse'!$B$17 | L7: =$K7/'Synthèse'!$B$9 | M7: ='Synthèse'!$B$13 | N7: 9 | O7: 5 | P7: =$O7/$M7 | Q7: =$L7+$P7 | R7: =$Q7/'Synthèse'!$B$30
A8: Pontlevoy | B8: Pontlevoy | C8: RIP | D8: Sud-Ouest | E8: 28 | F8: 88 | G8: 84 | H8: 0.67 | I8: =MAX($F8/'Synthèse'!$B$14,$G8/'Synthèse'!$B$15)+$H8/'Synthèse'!$B$16 | J8: =$I8*(1+'Synthèse'!$B$8) | K8: =(MAX($F8,$G8)+$H8)*(1+'Synthèse'!$B$8)/'Synthèse'!$B$17 | L8: =$K8/'Synthèse'!$B$9 | M8: ='Synthèse'!$B$13 | N8: 9 | O8: 5 | P8: =$O8/$M8 | Q8: =$L8+$P8 | R8: =$Q8/'Synthèse'!$B$30
A9: Vendôme | B9: Vendôme | C9: ZMD | D9: Nord | E9: 38 | F9: 38 | G9: 34 | H9: 0.67 | I9: =MAX($F9/'Synthèse'!$B$14,$G9/'Synthèse'!$B$15)+$H9/'Synthèse'!$B$16 | J9: =$I9*(1+'Synthèse'!$B$8) | K9: =(MAX($F9,$G9)+$H9)*(1+'Synthèse'!$B$8)/'Synthèse'!$B$17 | L9: =$K9/'Synthèse'!$B$9 | M9: ='Synthèse'!$B$12 | N9: 9 | O9: 5 | P9: =$O9/$M9 | Q9: =$L9+$P9 | R9: =$Q9/'Synthèse'!$B$30
A10: Épiais | B10: Épiais | C10: RIP | D10: Nord | E10: 24 | F10: 48 | G10: 50 | H10: 0.67 | I10: =MAX($F10/'Synthèse'!$B$14,$G10/'Synthèse'!$B$15)+$H10/'Synthèse'!$B$16 | J10: =$I10*(1+'Synthèse'!$B$8) | K10: =(MAX($F10,$G10)+$H10)*(1+'Synthèse'!$B$8)/'Synthèse'!$B$17 | L10: =$K10/'Synthèse'!$B$9 | M10: ='Synthèse'!$B$13 | N10: 6 | O10: 4 | P10: =$O10/$M10 | Q10: =$L10+$P10 | R10: =$Q10/'Synthèse'!$B$30
A11: Montoire-sur-le-Loir | B11: Montoire | C11: RIP | D11: Nord | E11: 50 | F11: 37 | G11: 48 | H11: 0.33 | I11: =MAX($F11/'Synthèse'!$B$14,$G11/'Synthèse'!$B$15)+$H11/'Synthèse'!$B$16 | J11: =$I11*(1+'Synthèse'!$B$8) | K11: =(MAX($F11,$G11)+$H11)*(1+'Synthèse'!$B$8)/'Synthèse'!$B$17 | L11: =$K11/'Synthèse'!$B$9 | M11: ='Synthèse'!$B$13 | N11: 9 | O11: 5 | P11: =$O11/$M11 | Q11: =$L11+$P11 | R11: =$Q11/'Synthèse'!$B$30
A12: Cormenon | B12: Cormenon | C12: RIP | D12: Nord | E12: 61 | F12: 18 | G12: 19 | H12: 0.33 | I12: =MAX($F12/'Synthèse'!$B$14,$G12/'Synthèse'!$B$15)+$H12/'Synthèse'!$B$16 | J12: =$I12*(1+'Synthèse'!$B$8) | K12: =(MAX($F12,$G12)+$H12)*(1+'Synthèse'!$B$8)/'Synthèse'!$B$17 | L12: =$K12/'Synthèse'!$B$9 | M12: ='Synthèse'!$B$13 | N12: 6 | O12: 4 | P12: =$O12/$M12 | Q12: =$L12+$P12 | R12: =$Q12/'Synthèse'!$B$30
A13: Crouy-sur-Cosson | B13: Crouy-sur-Cosson | C13: RIP | D13: Est | E13: 29 | F13: 52 | G13: 48 | H13: 0.33 | I13: =MAX($F13/'Synthèse'!$B$14,$G13/'Synthèse'!$B$15)+$H13/'Synthèse'!$B$16 | J13: =$I13*(1+'Synthèse'!$B$8) | K13: =(MAX($F13,$G13)+$H13)*(1+'Synthèse'!$B$8)/'Synthèse'!$B$17 | L13: =$K13/'Synthèse'!$B$9 | M13: ='Synthèse'!$B$13 | N13: 9 | O13: 5 | P13: =$O13/$M13 | Q13: =$L13+$P13 | R13: =$Q13/'Synthèse'!$B$30
A14: Vouzon | B14: Vouzon | C14: RIP | D14: Est | E14: 65 | F14: 31 | G14: 33 | H14: 0.33 | I14: =MAX($F14/'Synthèse'!$B$14,$G14/'Synthèse'!$B$15)+$H14/'Synthèse'!$B$16 | J14: =$I14*(1+'Synthèse'!$B$8) | K14: =(MAX($F14,$G14)+$H14)*(1+'Synthèse'!$B$8)/'Synthèse'!$B$17 | L14: =$K14/'Synthèse'!$B$9 | M14: ='Synthèse'!$B$13 | N14: 9 | O14: 5 | P14: =$O14/$M14 | Q14: =$L14+$P14 | R14: =$Q14/'Synthèse'!$B$30
A15: Mur-de-Sologne | B15: Mur-de-Sologne | C15: RIP | D15: Sologne Sud | E15: 38 | F15: 49 | G15: 36 | H15: 0.33 | I15: =MAX($F15/'Synthèse'!$B$14,$G15/'Synthèse'!$B$15)+$H15/'Synthèse'!$B$16 | J15: =$I15*(1+'Synthèse'!$B$8) | K15: =(MAX($F15,$G15)+$H15)*(1+'Synthèse'!$B$8)/'Synthèse'!$B$17 | L15: =$K15/'Synthèse'!$B$9 | M15: ='Synthèse'!$B$13 | N15: 9 | O15: 5 | P15: =$O15/$M15 | Q15: =$L15+$P15 | R15: =$Q15/'Synthèse'!$B$30
A16: Romorantin-Lanthenay | B16: Romorantin | C16: ZMD | D16: Sologne Sud | E16: 50 | F16: 44 | G16: 31 | H16: 0.33 | I16: =MAX($F16/'Synthèse'!$B$14,$G16/'Synthèse'!$B$15)+$H16/'Synthèse'!$B$16 | J16: =$I16*(1+'Synthèse'!$B$8) | K16: =(MAX($F16,$G16)+$H16)*(1+'Synthèse'!$B$8)/'Synthèse'!$B$17 | L16: =$K16/'Synthèse'!$B$9 | M16: ='Synthèse'!$B$12 | N16: 9 | O16: 5 | P16: =$O16/$M16 | Q16: =$L16+$P16 | R16: =$Q16/'Synthèse'!$B$30
A17: La Ferté-Imbault | B17: La Ferté-Imbault | C17: RIP | D17: Sologne Sud | E17: 66 | F17: 17 | G17: 13 | H17: 0.67 | I17: =MAX($F17/'Synthèse'!$B$14,$G17/'Synthèse'!$B$15)+$H17/'Synthèse'!$B$16 | J17: =$I17*(1+'Synthèse'!$B$8) | K17: =(MAX($F17,$G17)+$H17)*(1+'Synthèse'!$B$8)/'Synthèse'!$B$17 | L17: =$K17/'Synthèse'!$B$9 | M17: ='Synthèse'!$B$13 | N17: 6 | O17: 4 | P17: =$O17/$M17 | Q17: =$L17+$P17 | R17: =$Q17/'Synthèse'!$B$30
A18: TOTAL DÉPARTEMENT 41 | F18: =SUM(F6:F17) | G18: =SUM(G6:G17) | H18: =SUM(H6:H17) | K18: =SUM(K6:K17) | L18: =SUM(L6:L17) | N18: =SUM(N6:N17) | O18: =SUM(O6:O17) | P18: =SUM(P6:P17) | Q18: =SUM(Q6:Q17) | R18: =SUM(R6:R17)
A20: Légende :
A21: Cellules jaunes / texte bleu = saisie utilisateur · texte vert = repris de l'onglet « Grille SAV » · texte noir = formule
A22: « Pointe /jour » retient le mois le plus chargé entre octobre et mars, secteur par secteur, et y ajoute le B2B. Le fichier source, lui, ne dimensionne que sur mars — d'où une sous-estimation sur le 41, où octobre est le mois haut (705 interventions contre 656).

Sheet Moteur dispo
A1: MOTEUR DE DISPONIBILITÉ — RÉSERVATION SAV & BASCULE PROD
A2: C'est le mécanisme qui libère de la disponibilité sans embaucher : on réserve large pour le SAV, et tout créneau non vendu redevient de la PROD à J-1.
A4: RÈGLES D'EXPLOITATION
A5: N° | B5: Moment | C5: Règle | D5: Effet
A6: R1 | B6: Permanent | C6: La tournée est figée : technicien × jour × secteur ne change jamais (voir onglet « Grille SAV »). | D6: Distances maîtrisées, techniciens sur des secteurs qu'ils connaissent.
A7: R2 | B7: Permanent | C7: Chaque secteur est visité 3 fois/semaine, rythme Lundi-Mercredi-Vendredi ou Mardi-Jeudi-Samedi. | D7: Quel que soit le jour d'appel, il existe un passage à J+1 ou J+2.
A8: R3 | B8: J-7 à J-5 | C8: La PROD se pose uniquement sur les créneaux non réservés au SAV, dans le carnet J+5 à J+7. | D8: Le client PROD obtient bien un RDV à J+5/J+6/J+7.
A9: R4 | B9: J-2, 18 h | C9: Ouverture à la prise de RDV SAV des créneaux réservés du jour J. | D9: Le client SAV qui appelle voit de la dispo à J+1 et J+2.
A10: R5 | B10: J-1, 18 h | C10: BASCULE : tout créneau SAV encore libre pour le lendemain est réaffecté à une intervention PROD du même secteur, puisée dans le carnet J+5/J+7. | D10: Aucun créneau perdu. C'est ce qui rend la réservation SAV quasi gratuite.
A11: R6 | B11: J-1, 18 h | C11: La bascule n'est possible que si le carnet PROD du secteur contient au moins 2 interventions en attente. | D11: Sur les petits secteurs (Cormenon, La Ferté-Imbault), maintenir un stock PROD tampon.
A12: R7 | B12: Jour J | C12: Un SAV urgent arrivé après la bascule prend la place d'une PROD du jour, qui repart en J+5. | D12: La PROD absorbe l'aléa, jamais le SAV — c'est elle qui a le délai le plus long.
A13: R8 | B13: Hebdo | C13: Si le taux de remplissage SAV d'un secteur dépasse 4 semaines de suite le seuil de l'onglet Synthèse, augmenter la réservation de ce secteur. | D13: Le curseur de réservation suit la demande réelle.
A15: TABLEAU DE BORD QUOTIDIEN — À REMPLIR CHAQUE SOIR AVANT LA BASCULE
A16: Colonne D (jaune) : nombre de RDV SAV réellement pris pour le lendemain. Le reste se calcule.
A17: Secteur visité demain | B17: Créneaux du jour | C17: dont réservés SAV | D17: RDV SAV pris (à saisir) | E17: Créneaux SAV libres | F17: PROD à injecter (bascule) | G17: Stock PROD requis dans le secteur | H17: Alerte
A18: Blois | B18: 7 | C18: 4 | D18: 0 | E18: =MAX(0,$C18-$D18) | F18: =ROUND($E18*'Synthèse'!$B$9/'Synthèse'!$B$13,0) | G18: =MAX(2,$F18) | H18: =IF($D18>$C18,"Débordement SAV : basculer une PROD du jour",IF($F18=0,"Journée pleine en SAV","Injecter "&TEXT($F18,"0")&" PROD du carnet J+5/J+7"))
A19: Pontlevoy | B19: 5 | C19: 3 | D19: 0 | E19: =MAX(0,$C19-$D19) | F19: =ROUND($E19*'Synthèse'!$B$9/'Synthèse'!$B$13,0) | G19: =MAX(2,$F19) | H19: =IF($D19>$C19,"Débordement SAV : basculer une PROD du jour",IF($F19=0,"Journée pleine en SAV","Injecter "&TEXT($F19,"0")&" PROD du carnet J+5/J+7"))
A20: Vendôme | B20: 5 | C20: 3 | D20: 0 | E20: =MAX(0,$C20-$D20) | F20: =ROUND($E20*'Synthèse'!$B$9/'Synthèse'!$B$13,0) | G20: =MAX(2,$F20) | H20: =IF($D20>$C20,"Débordement SAV : basculer une PROD du jour",IF($F20=0,"Journée pleine en SAV","Injecter "&TEXT($F20,"0")&" PROD du carnet J+5/J+7"))
A21: Épiais | B21: 5 | C21: 2 | D21: 0 | E21: =MAX(0,$C21-$D21) | F21: =ROUND($E21*'Synthèse'!$B$9/'Synthèse'!$B$13,0) | G21: =MAX(2,$F21) | H21: =IF($D21>$C21,"Débordement SAV : basculer une PROD du jour",IF($F21=0,"Journée pleine en SAV","Injecter "&TEXT($F21,"0")&" PROD du carnet J+5/J+7"))
A22: Mur-de-Sologne | B22: 5 | C22: 3 | D22: 0 | E22: =MAX(0,$C22-$D22) | F22: =ROUND($E22*'Synthèse'!$B$9/'Synthèse'!$B$13,0) | G22: =MAX(2,$F22) | H22: =IF($D22>$C22,"Débordement SAV : basculer une PROD du jour",IF($F22=0,"Journée pleine en SAV","Injecter "&TEXT($F22,"0")&" PROD du carnet J+5/J+7"))
A23: Crouy-sur-Cosson | B23: 5 | C23: 3 | D23: 0 | E23: =MAX(0,$C23-$D23) | F23: =ROUND($E23*'Synthèse'!$B$9/'Synthèse'!$B$13,0) | G23: =MAX(2,$F23) | H23: =IF($D23>$C23,"Débordement SAV : basculer une PROD du jour",IF($F23=0,"Journée pleine en SAV","Injecter "&TEXT($F23,"0")&" PROD du carnet J+5/J+7"))
A24: Valencisse | B24: 5 | C24: 3 | D24: 0 | E24: =MAX(0,$C24-$D24) | F24: =ROUND($E24*'Synthèse'!$B$9/'Synthèse'!$B$13,0) | G24: =MAX(2,$F24) | H24: =IF($D24>$C24,"Débordement SAV : basculer une PROD du jour",IF($F24=0,"Journée pleine en SAV","Injecter "&TEXT($F24,"0")&" PROD du carnet J+5/J+7"))
A25: Montoire-sur-le-Loir | B25: 5 | C25: 3 | D25: 0 | E25: =MAX(0,$C25-$D25) | F25: =ROUND($E25*'Synthèse'!$B$9/'Synthèse'!$B$13,0) | G25: =MAX(2,$F25) | H25: =IF($D25>$C25,"Débordement SAV : basculer une PROD du jour",IF($F25=0,"Journée pleine en SAV","Injecter "&TEXT($F25,"0")&" PROD du carnet J+5/J+7"))
A26: Cormenon | B26: 5 | C26: 2 | D26: 0 | E26: =MAX(0,$C26-$D26) | F26: =ROUND($E26*'Synthèse'!$B$9/'Synthèse'!$B$13,0) | G26: =MAX(2,$F26) | H26: =IF($D26>$C26,"Débordement SAV : basculer une PROD du jour",IF($F26=0,"Journée pleine en SAV","Injecter "&TEXT($F26,"0")&" PROD du carnet J+5/J+7"))
A27: Romorantin-Lanthenay | B27: 5 | C27: 3 | D27: 0 | E27: =MAX(0,$C27-$D27) | F27: =ROUND($E27*'Synthèse'!$B$9/'Synthèse'!$B$13,0) | G27: =MAX(2,$F27) | H27: =IF($D27>$C27,"Débordement SAV : basculer une PROD du jour",IF($F27=0,"Journée pleine en SAV","Injecter "&TEXT($F27,"0")&" PROD du carnet J+5/J+7"))
A28: La Ferté-Imbault | B28: 5 | C28: 2 | D28: 0 | E28: =MAX(0,$C28-$D28) | F28: =ROUND($E28*'Synthèse'!$B$9/'Synthèse'!$B$13,0) | G28: =MAX(2,$F28) | H28: =IF($D28>$C28,"Débordement SAV : basculer une PROD du jour",IF($F28=0,"Journée pleine en SAV","Injecter "&TEXT($F28,"0")&" PROD du carnet J+5/J+7"))
A29: Vouzon | B29: 5 | C29: 3 | D29: 0 | E29: =MAX(0,$C29-$D29) | F29: =ROUND($E29*'Synthèse'!$B$9/'Synthèse'!$B$13,0) | G29: =MAX(2,$F29) | H29: =IF($D29>$C29,"Débordement SAV : basculer une PROD du jour",IF($F29=0,"Journée pleine en SAV","Injecter "&TEXT($F29,"0")&" PROD du carnet J+5/J+7"))
A30: TOTAL JOUR | B30: =SUM(B18:B29) | C30: =SUM(C18:C29) | D30: =SUM(D18:D29) | E30: =SUM(E18:E29) | F30: =SUM(F18:F29) | H30: ="Taux de remplissage SAV du jour : "&TEXT(IFERROR($D30/$C30,0),"0%")
A32: Point d'équilibre : la grille sert 142 interventions PROD en direct, alors que la demande PROD +10 % est de 185/semaine. Les 43 manquantes viennent de la bascule R5.
A33: Il faut donc qu'environ 60 créneaux SAV restent libres chaque semaine, soit un taux de remplissage SAV inférieur à 60 %. Au-delà, la PROD décroche du délai J+5/J+7 : c'est le seuil d'alerte à surveiller.

Sheet Distances
A1: COHÉRENCE GÉOGRAPHIQUE — DISTANCES ROUTIÈRES ESTIMÉES (km)
A2: Estimation = distance à vol d'oiseau × 1,25, majorée de 8 km entre les deux rives de la Loire (ponts de Blois, Chaumont, Muides, Beaugency). À confirmer par votre outil de tournées.
B4: Blois | C4: Valencisse | D4: Pontlevoy | E4: Vendôme | F4: Épiais | G4: Montoire-sur-le-Loir | H4: Cormenon | I4: Crouy-sur-Cosson | J4: Vouzon | K4: Mur-de-Sologne | L4: Romorantin-Lanthenay | M4: La Ferté-Imbault
A5: Blois | B5: — | C5: 11 | D5: 28 | E5: 38 | F5: 24 | G5: 50 | H5: 61 | I5: 29 | J5: 65 | K5: 38 | L5: 50 | M5: 66
A6: Valencisse | B6: 11 | C6: — | D6: 35 | E6: 32 | F6: 28 | G6: 40 | H6: 55 | I6: 47 | J6: 84 | K6: 55 | L6: 67 | M6: 84
A7: Pontlevoy | B7: 28 | C7: 35 | D7: — | E7: 66 | F7: 60 | G7: 70 | H7: 90 | I7: 52 | J7: 81 | K7: 34 | L7: 46 | M7: 68
A8: Vendôme | B8: 38 | C8: 32 | D8: 66 | E8: — | F8: 29 | G8: 20 | H8: 24 | I8: 61 | J8: 99 | K8: 85 | L8: 96 | M8: 110
A9: Épiais | B9: 24 | C9: 28 | D9: 60 | E9: 29 | F9: — | G9: 48 | H9: 46 | I9: 33 | J9: 70 | K9: 65 | L9: 74 | M9: 84
A10: Montoire-sur-le-Loir | B10: 50 | C10: 40 | D10: 70 | E10: 20 | F10: 48 | G10: — | H10: 30 | I10: 78 | J10: 117 | K10: 95 | L10: 107 | M10: 123
A11: Cormenon | B11: 61 | C11: 55 | D11: 90 | E11: 24 | F11: 46 | G11: 30 | H11: — | I11: 78 | J11: 113 | K11: 107 | L11: 118 | M11: 129
A12: Crouy-sur-Cosson | B12: 29 | C12: 47 | D12: 52 | E12: 61 | F12: 33 | G12: 78 | H12: 78 | I12: — | J12: 38 | K12: 41 | L12: 47 | M12: 52
A13: Vouzon | B13: 65 | C13: 84 | D13: 81 | E13: 99 | F13: 70 | G13: 117 | H13: 113 | I13: 38 | J13: — | K13: 54 | L13: 49 | M13: 37
A14: Mur-de-Sologne | B14: 38 | C14: 55 | D14: 34 | E14: 85 | F14: 65 | G14: 95 | H14: 107 | I14: 41 | J14: 54 | K14: — | L14: 13 | M14: 34
A15: Romorantin-Lanthenay | B15: 50 | C15: 67 | D15: 46 | E15: 96 | F15: 74 | G15: 107 | H15: 118 | I15: 47 | J15: 49 | K15: 13 | L15: — | M15: 22
A16: La Ferté-Imbault | B16: 66 | C16: 84 | D16: 68 | E16: 110 | F16: 84 | G16: 123 | H16: 129 | I16: 52 | J16: 37 | K16: 34 | L16: 22 | M16: —
A18: Vert ≤ 30 km : enchaînement de deux demi-journées acceptable · Orange 31-50 km : à éviter dans la même journée · Rouge > 50 km : incohérent
A20: CE QUE CELA CHANGE PAR RAPPORT À LA GRILLE ACTUELLE (capture d'écran)
A21: Point | B21: Grille actuelle | C21: Grille proposée
A22: Cluster T5 | B22: Crouy · Épiais · Vouzon · Cormenon · Blois — soit Vouzon↔Cormenon 113 km dans un même secteur. | C22: Cormenon repart au Nord (Vendômois/Perche). T6 ne garde que Crouy et Vouzon, distants de 38 km.
A23: Jeudi T5 | B23: Épiais matin → Cormenon après-midi : 46 km entre les deux vacations. | C23: Montoire matin → Cormenon après-midi : 30 km, et les deux sont dans le même cluster Nord.
A24: Enchaînements | B24: Jusqu'à 46 km entre matin et après-midi. | C24: Maximum 30 km : Vendôme→Épiais 29, Montoire→Cormenon 30, Romorantin→La Ferté 22.
